Workbook

Sheet Quotazioni calciatori
A1: CognomeSquadra | B1: CognomeNomeSquadra | C1: Codice | D1: Cognome | E1: Nome | F1: Squadra | G1: Ruolo | H1: Giornata | I1: Quotazione | J1: Cerca | K1: Trova | L1: IdCerca | M1: IdRicerca | N1: ID LEGHE | O1: FVM | P1: update
A2: =CONCATENATE(D2,F2) -> BellanovaAtalanta | B2: =CONCATENATE(D2," ",E2,F2) -> Bellanova R.Atalanta | C2: 1065433 | D2: Bellanova | E2: R. | F2: Atalanta | G2: D | H2: 6 | I2: 12 | J2: =VLOOKUP(A2,'Leghe Fantacalcio'!A:I,1,FALSE) -> BellanovaAtalanta | K2: =VLOOKUP(B2,'Leghe Fantacalcio'!A:I,1,FALSE) -> #N/A | L2: =IF(ISNA(VLOOKUP(A2,'Leghe Fantacalcio'!A:I,2,FALSE)),"",VLOOKUP(A2,'Leghe Fantacalcio'!A:I,2,FALSE)) -> 4887 | M2: =IF(ISNA(VLOOKUP(B2,'Leghe Fantacalcio'!A:I,2,FALSE)),"",VLOOKUP(B2,'Leghe Fantacalcio'!A:I,2,FALSE)) | N2: =IFERROR(VALUE(CONCATENATE(L2,M2)),"") -> 4887 | O2: =IFERROR(VLOOKUP(N2,'Leghe Fantacalcio'!B:I,8,FALSE),0) -> 16 | P2: =CONCATENATE("update giocatori set fvm = ",O2," where id = ",C2,";") -> update giocatori set fvm = 16 where id = 1065433;
A3: =CONCATENATE(D3,F3) -> BernasconiAtalanta | B3: =CONCATENATE(D3," ",E3,F3) -> Bernasconi L.Atalanta | C3: 1102450 | D3: Bernasconi | E3: L. | F3: Atalanta | G3: D | H3: 6 | I3: 11 | J3: =VLOOKUP(A3,'Leghe Fantacalcio'!A:I,1,FALSE) -> BernasconiAtalanta | K3: =VLOOKUP(B3,'Leghe Fantacalcio'!A:I,1,FALSE) -> #N/A | L3: =IF(ISNA(VLOOKUP(A3,'Leghe Fantacalcio'!A:I,2,FALSE)),"",VLOOKUP(A3,'Leghe Fantacalcio'!A:I,2,FALSE)) -> 7219 | M3: =IF(ISNA(VLOOKUP(B3,'Leghe Fantacalcio'!A:I,2,FALSE)),"",VLOOKUP(B3,'Leghe Fantacalcio'!A:I,2,FALSE)) | N3: =IFERROR(VALUE(CONCATENATE(L3,M3)),"") -> 7219 | O3: =IFERROR(VLOOKUP(N3,'Leghe Fantacalcio'!B:I,8,FALSE),0) -> 14 | P3: =CONCATENATE("update giocatori set fvm = ",O3," where id = ",C3,";") -> update giocatori set fvm = 14 where id = 1102450;
A4: =CONCATENATE(D4,F4) -> CarnesecchiAtalanta | B4: =CONCATENATE(D4," ",E4,F4) -> Carnesecchi M.Atalanta | C4: 1070334 | D4: Carnesecchi | E4: M. | F4: Atalanta | G4: P | H4: 6 | I4: 20 | J4: =VLOOKUP(A4,'Leghe Fantacalcio'!A:I,1,FALSE) -> CarnesecchiAtalanta | K4: =VLOOKUP(B4,'Leghe Fantacalcio'!A:I,1,FALSE) -> #N/A | L4: =IF(ISNA(VLOOKUP(A4,'Leghe Fantacalcio'!A:I,2,FALSE)),"",VLOOKUP(A4,'Leghe Fantacalcio'!A:I,2,FALSE)) -> 4431 | M4: =IF(ISNA(VLOOKUP(B4,'Leghe Fantacalcio'!A:I,2,FALSE)),"",VLOOKUP(B4,'Leghe Fantacalcio'!A:I,2,FALSE)) | N4: =IFERROR(VALUE(CONCATENATE(L4,M4)),"") -> 4431 | O4: =IFERROR(VLOOKUP(N4,'Leghe Fantacalcio'!B:I,8,FALSE),0) -> 56 | P4: =CONCATENATE("update giocatori set fvm = ",O4," where id = ",C4,";") -> update giocatori set fvm = 56 where id = 1070334;
A5: =CONCATENATE(D5,F5) -> De KetelaereAtalanta | B5: =CONCATENATE(D5," ",E5,F5) -> De Ketelaere C.Atalanta | C5: 1095519 | D5: De Ketelaere | E5: C. | F5: Atalanta | G5: A | H5: 6 | I5: 33 | J5: =VLOOKUP(A5,'Leghe Fantacalcio'!A:I,1,FALSE) -> De KetelaereAtalanta | K5: =VLOOKUP(B5,'Leghe Fantacalcio'!A:I,1,FALSE) -> #N/A | L5: =IF(ISNA(VLOOKUP(A5,'Leghe Fantacalcio'!A:I,2,FALSE)),"",VLOOKUP(A5,'Leghe Fantacalcio'!A:I,2,FALSE)) -> 5995 | M5: =IF(ISNA(VLOOKUP(B5,'Leghe Fantacalcio'!A:I,2,FALSE)),"",VLOOKUP(B5,'Leghe Fantacalcio'!A:I,2,FALSE)) | N5: =IFERROR(VALUE(CONCATENATE(L5,M5)),"") -> 5995 | O5: =IFERROR(VLOOKUP(N5,'Leghe Fantacalcio'!B:I,8,FALSE),0) -> 64 | P5: =CONCATENATE("update giocatori set fvm = ",O5," where id = ",C5,";") -> update giocatori set fvm = 64 where id = 1095519;
A6: =CONCATENATE(D6,F6) -> Ederson D.S.Atalanta | B6: =CONCATENATE(D6," ",E6,F6) -> Ederson D.S. Atalanta | C6: 1112712 | D6: Ederson D.S. | F6: Atalanta | G6: C | H6: 6 | I6: 31 | J6: =VLOOKUP(A6,'Leghe Fantacalcio'!A:I,1,FALSE) -> Ederson D.S.Atalanta | K6: =VLOOKUP(B6,'Leghe Fantacalcio'!A:I,1,FALSE) -> #N/A | L6: =IF(ISNA(VLOOKUP(A6,'Leghe Fantacalcio'!A:I,2,FALSE)),"",VLOOKUP(A6,'Leghe Fantacalcio'!A:I,2,FALSE)) -> 5792 | M6: =IF(ISNA(VLOOKUP(B6,'Leghe Fantacalcio'!A:I,2,FALSE)),"",VLOOKUP(B6,'Leghe Fantacalcio'!A:I,2,FALSE)) | N6: =IFERROR(VALUE(CONCATENATE(L6,M6)),"") -> 5792 | O6: =IFERROR(VLOOKUP(N6,'Leghe Fantacalcio'!B:I,8,FALSE),0) -> 45 | P6: =CONCATENATE("update giocatori set fvm = ",O6," where id = ",C6,";") -> update giocatori set fvm = 45 where id = 1112712;
A7: =CONCATENATE(D7,F7) -> ElmasAtalanta | B7: =CONCATENATE(D7," ",E7,F7) -> Elmas E.Atalanta | C7: 1053662 | D7: Elmas | E7: E. | F7: Atalanta | G7: C | H7: 6 | I7: 24 | J7: =VLOOKUP(A7,'Leghe Fantacalcio'!A:I,1,FALSE) -> ElmasAtalanta | K7: =VLOOKUP(B7,'Leghe Fantacalcio'!A:I,1,FALSE) -> #N/A | L7: =IF(ISNA(VLOOKUP(A7,'Leghe Fantacalcio'!A:I,2,FALSE)),"",VLOOKUP(A7,'Leghe Fantacalcio'!A:I,2,FALSE)) -> 4479 | M7: =IF(ISNA(VLOOKUP(B7,'Leghe Fantacalcio'!A:I,2,FALSE)),"",VLOOKUP(B7,'Leghe Fantacalcio'!A:I,2,FALSE)) | N7: =IFERROR(VALUE(CONCATENATE(L7,M7)),"") -> 4479 | O7: =IFERROR(VLOOKUP(N7,'Leghe Fantacalcio'!B:I,8,FALSE),0) -> 17 | P7: =CONCATENATE("update giocatori set fvm = ",O7," where id = ",C7,";") -> update giocatori set fvm = 17 where id = 1053662;
A8: =CONCATENATE(D8,F8) -> GaetanoAtalanta | B8: =CONCATENATE(D8," ",E8,F8) -> Gaetano G.Atalanta | C8: 1067792 | D8: Gaetano | E8: G. | F8: Atalanta | G8: C | H8: 6 | I8: 15 | J8: =VLOOKUP(A8,'Leghe Fantacalcio'!A:I,1,FALSE) -> GaetanoAtalanta | K8: =VLOOKUP(B8,'Leghe Fantacalcio'!A:I,1,FALSE) -> #N/A | L8: =IF(ISNA(VLOOKUP(A8,'Leghe Fantacalcio'!A:I,2,FALSE)),"",VLOOKUP(A8,'Leghe Fantacalcio'!A:I,2,FALSE)) -> 4364 | M8: =IF(ISNA(VLOOKUP(B8,'Leghe Fantacalcio'!A:I,2,FALSE)),"",VLOOKUP(B8,'Leghe Fantacalcio'!A:I,2,FALSE)) | N8: =IFERROR(VALUE(CONCATENATE(L8,M8)),"") -> 4364 | O8: =IFERROR(VLOOKUP(N8,'Leghe Fantacalcio'!B:I,8,FALSE),0) -> 23 | P8: =CONCATENATE("update giocatori set fvm = ",O8," where id = ",C8,";") -> update giocatori set fvm = 23 where id = 1067792;
A9: =CONCATENATE(D9,F9) -> HienAtalanta | B9: =CONCATENATE(D9," ",E9,F9) -> Hien I.Atalanta | C9: 1106221 | D9: Hien | E9: I. | F9: Atalanta | G9: D | H9: 6 | I9: 10 | J9: =VLOOKUP(A9,'Leghe Fantacalcio'!A:I,1,FALSE) -> HienAtalanta | K9: =VLOOKUP(B9,'Leghe Fantacalcio'!A:I,1,FALSE) -> #N/A | L9: =IF(ISNA(VLOOKUP(A9,'Leghe Fantacalcio'!A:I,2,FALSE)),"",VLOOKUP(A9,'Leghe Fantacalcio'!A:I,2,FALSE)) -> 6046 | M9: =IF(ISNA(VLOOKUP(B9,'Leghe Fantacalcio'!A:I,2,FALSE)),"",VLOOKUP(B9,'Leghe Fantacalcio'!A:I,2,FALSE)) | N9: =IFERROR(VALUE(CONCATENATE(L9,M9)),"") -> 6046 | O9: =IFERROR(VLOOKUP(N9,'Leghe Fantacalcio'!B:I,8,FALSE),0) -> 10 | P9: =CONCATENATE("update giocatori set fvm = ",O9," where id = ",C9,";") -> update giocatori set fvm = 10 where id = 1106221;
A10: =CONCATENATE(D10,F10) -> KessièAtalanta | B10: =CONCATENATE(D10," ",E10,F10) -> Kessiè F.Atalanta | C10: 1050707 | D10: Kessiè | E10: F. | F10: Atalanta | G10: C | H10: 6 | I10: 30 | J10: =VLOOKUP(A10,'Leghe Fantacalcio'!A:I,1,FALSE) -> KessièAtalanta | K10: =VLOOKUP(B10,'Leghe Fantacalcio'!A:I,1,FALSE) -> #N/A | L10: =IF(ISNA(VLOOKUP(A10,'Leghe Fantacalcio'!A:I,2,FALSE)),"",VLOOKUP(A10,'Leghe Fantacalcio'!A:I,2,FALSE)) -> 1850 | M10: =IF(ISNA(VLOOKUP(B10,'Leghe Fantacalcio'!A:I,2,FALSE)),"",VLOOKUP(B10,'Leghe Fantacalcio'!A:I,2,FALSE)) | N10: =IFERROR(VALUE(CONCATENATE(L10,M10)),"") -> 1850 | O10: =IFERROR(VLOOKUP(N10,'Leghe Fantacalcio'!B:I,8,FALSE),0) -> 33 | P10: =CONCATENATE("update giocatori set fvm = ",O10," where id = ",C10,";") -> update giocatori set fvm = 33 where id = 1050707;
A11: =CONCATENATE(D11,F11) -> KolasinacAtalanta | B11: =CONCATENATE(D11," ",E11,F11) -> Kolasinac S.Atalanta | C11: 1017350 | D11: Kolasinac | E11: S. | F11: Atalanta | G11: D | H11: 6 | I11: 6 | J11: =VLOOKUP(A11,'Leghe Fantacalcio'!A:I,1,FALSE) -> KolasinacAtalanta | K11: =VLOOKUP(B11,'Leghe Fantacalcio'!A:I,1,FALSE) -> #N/A | L11: =IF(ISNA(VLOOKUP(A11,'Leghe Fantacalcio'!A:I,2,FALSE)),"",VLOOKUP(A11,'Leghe Fantacalcio'!A:I,2,FALSE)) -> 2640 | M11: =IF(ISNA(VLOOKUP(B11,'Leghe Fantacalcio'!A:I,2,FALSE)),"",VLOOKUP(B11,'Leghe Fantacalcio'!A:I,2,FALSE)) | N11: =IFERROR(VALUE(CONCATENATE(L11,M11)),"") -> 2640 | O11: =IFERROR(VLOOKUP(N11,'Leghe Fantacalcio'!B:I,8,FALSE),0) -> 11 | P11: =CONCATENATE("update giocatori set fvm = ",O11," where id = ",C11,";") -> update giocatori set fvm = 11 where id = 1017350;
A12: =CONCATENATE(D12,F12) -> KossounouAtalanta | B12: =CONCATENATE(D12," ",E12,F12) -> Kossounou O.Atalanta | C12: 1095516 | D12: Kossounou | E12: O. | F12: Atalanta | G12: D | H12: 6 | I12: 9 | J12: =VLOOKUP(A12,'Leghe Fantacalcio'!A:I,1,FALSE) -> KossounouAtalanta | K12: =VLOOKUP(B12,'Leghe Fantacalcio'!A:I,1,FALSE) -> #N/A | L12: =IF(ISNA(VLOOKUP(A12,'Leghe Fantacalcio'!A:I,2,FALSE)),"",VLOOKUP(A12,'Leghe Fantacalcio'!A:I,2,FALSE)) -> 5578 | M12: =IF(ISNA(VLOOKUP(B12,'Leghe Fantacalcio'!A:I,2,FALSE)),"",VLOOKUP(B12,'Leghe Fantacalcio'!A:I,2,FALSE)) | N12: =IFERROR(VALUE(CONCATENATE(L12,M12)),"") -> 5578 | O12: =IFERROR(VLOOKUP(N12,'Leghe Fantacalcio'!B:I,8,FALSE),0) -> 12 | P12: =CONCATENATE("update giocatori set fvm = ",O12," where id = ",C12,";") -> update giocatori set fvm = 12 where id = 1095516;
A13: =CONCATENATE(D13,F13) -> KristensenAtalanta | B13: =CONCATENATE(D13," ",E13,F13) -> Kristensen T.Atalanta | C13: 1102383 | D13: Kristensen | E13: T. | F13: Atalanta | G13: D | H13: 6 | I13: 8 | J13: =VLOOKUP(A13,'Leghe Fantacalcio'!A:I,1,FALSE) -> #N/A | K13: =VLOOKUP(B13,'Leghe Fantacalcio'!A:I,1,FALSE) -> Kristensen T.Atalanta | L13: =IF(ISNA(VLOOKUP(A13,'Leghe Fantacalcio'!A:I,2,FALSE)),"",VLOOKUP(A13,'Leghe Fantacalcio'!A:I,2,FALSE)) | M13: =IF(ISNA(VLOOKUP(B13,'Leghe Fantacalcio'!A:I,2,FALSE)),"",VLOOKUP(B13,'Leghe Fantacalcio'!A:I,2,FALSE)) -> 6485 | N13: =IFERROR(VALUE(CONCATENATE(L13,M13)),"") -> 6485 | O13: =IFERROR(VLOOKUP(N13,'Leghe Fantacalcio'!B:I,8,FALSE),0) -> 14 | P13: =CONCATENATE("update giocatori set fvm = ",O13," where id = ",C13,";") -> update giocatori set fvm = 14 where id = 1102383;
A14: =CONCATENATE(D14,F14) -> KrstovicAtalanta | B14: =CONCATENATE(D14," ",E14,F14) -> Krstovic N.Atalanta | C14: 1095769 | D14: Krstovic | E14: N. | F14: Atalanta | G14: A | H14: 6 | I14: 41 | J14: =VLOOKUP(A14,'Leghe Fantacalcio'!A:I,1,FALSE) -> KrstovicAtalanta | K14: =VLOOKUP(B14,'Leghe Fantacalcio'!A:I,1,FALSE) -> #N/A | L14: =IF(ISNA(VLOOKUP(A14,'Leghe Fantacalcio'!A:I,2,FALSE)),"",VLOOKUP(A14,'Leghe Fantacalcio'!A:I,2,FALSE)) -> 6435 | M14: =IF(ISNA(VLOOKUP(B14,'Leghe Fantacalcio'!A:I,2,FALSE)),"",VLOOKUP(B14,'Leghe Fantacalcio'!A:I,2,FALSE)) | N14: =IFERROR(VALUE(CONCATENATE(L14,M14)),"") -> 6435 | O14: =IFERROR(VLOOKUP(N14,'Leghe Fantacalcio'!B:I,8,FALSE),0) -> 80 | P14: =CONCATENATE("update giocatori set fvm = ",O14," where id = ",C14,";") -> update giocatori set fvm = 80 where id = 1095769;
A15: =CONCATENATE(D15,F15) -> ManzoniAtalanta | B15: =CONCATENATE(D15," ",E15,F15) -> Manzoni A.Atalanta | C15: 1118814 | D15: Manzoni | E15: A. | F15: Atalanta | G15: C | H15: 6 | I15: 1 | J15: =VLOOKUP(A15,'Leghe Fantacalcio'!A:I,1,FALSE) -> #N/A | K15: =VLOOKUP(B15,'Leghe Fantacalcio'!A:I,1,FALSE) -> #N/A | L15: =IF(ISNA(VLOOKUP(A15,'Leghe Fantacalcio'!A:I,2,FALSE)),"",VLOOKUP(A15,'Leghe Fantacalcio'!A:I,2,FALSE)) | M15: =IF(ISNA(VLOOKUP(B15,'Leghe Fantacalcio'!A:I,2,FALSE)),"",VLOOKUP(B15,'Leghe Fantacalcio'!A:I,2,FALSE)) | N15: =IFERROR(VALUE(CONCATENATE(L15,M15)),"") | O15: =IFERROR(VLOOKUP(N15,'Leghe Fantacalcio'!B:I,8,FALSE),0) -> 0 | P15: =CONCATENATE("update giocatori set fvm = ",O15," where id = ",C15,";") -> update giocatori set fvm = 0 where id = 1118814;
A16: =CONCATENATE(D16,F16) -> ObricAtalanta | B16: =CONCATENATE(D16," ",E16,F16) -> Obric R.Atalanta | C16: 1119840 | D16: Obric | E16: R. | F16: Atalanta | G16: D | H16: 6 | I16: 1 | J16: =VLOOKUP(A16,'Leghe Fantacalcio'!A:I,1,FALSE) -> #N/A | K16: =VLOOKUP(B16,'Leghe Fantacalcio'!A:I,1,FALSE) -> #N/A | L16: =IF(ISNA(VLOOKUP(A16,'Leghe Fantacalcio'!A:I,2,FALSE)),"",VLOOKUP(A16,'Leghe Fantacalcio'!A:I,2,FALSE)) | M16: =IF(ISNA(VLOOKUP(B16,'Leghe Fantacalcio'!A:I,2,FALSE)),"",VLOOKUP(B16,'Leghe Fantacalcio'!A:I,2,FALSE)) | N16: =IFERROR(VALUE(CONCATENATE(L16,M16)),"") | O16: =IFERROR(VLOOKUP(N16,'Leghe Fantacalcio'!B:I,8,FALSE),0) -> 0 | P16: =CONCATENATE("update giocatori set fvm = ",O16," where id = ",C16,";") -> update giocatori set fvm = 0 where id = 1119840;
A17: =CONCATENATE(D17,F17) -> PasalicAtalanta | B17: =CONCATENATE(D17," ",E17,F17) -> Pasalic M.Atalanta | C17: 1040264 | D17: Pasalic | E17: M. | F17: Atalanta | G17: C | H17: 6 | I17: 21 | J17: =VLOOKUP(A17,'Leghe Fantacalcio'!A:I,1,FALSE) -> PasalicAtalanta | K17: =VLOOKUP(B17,'Leghe Fantacalcio'!A:I,1,FALSE) -> #N/A | L17: =IF(ISNA(VLOOKUP(A17,'Leghe Fantacalcio'!A:I,2,FALSE)),"",VLOOKUP(A17,'Leghe Fantacalcio'!A:I,2,FALSE)) -> 2077 | M17: =IF(ISNA(VLOOKUP(B17,'Leghe Fantacalcio'!A:I,2,FALSE)),"",VLOOKUP(B17,'Leghe Fantacalcio'!A:I,2,FALSE)) | N17: =IFERROR(VALUE(CONCATENATE(L17,M17)),"") -> 2077 | O17: =IFERROR(VLOOKUP(N17,'Leghe Fantacalcio'!B:I,8,FALSE),0) -> 18 | P17: =CONCATENATE("update giocatori set fvm = ",O17," where id = ",C17,";") -> update giocatori set fvm = 18 where id = 1040264;
A18: =CONCATENATE(D18,F18) -> PompeiAtalanta | B18: =CONCATENATE(D18," ",E18,F18) -> Pompei T.Atalanta | C18: 1120636 | D18: Pompei | E18: T. | F18: Atalanta | G18: P | H18: 6 | I18: 1 | J18: =VLOOKUP(A18,'Leghe Fantacalcio'!A:I,1,FALSE) -> PompeiAtalanta | K18: =VLOOKUP(B18,'Leghe Fantacalcio'!A:I,1,FALSE) -> #N/A | L18: =IF(ISNA(VLOOKUP(A18,'Leghe Fantacalcio'!A:I,2,FALSE)),"",VLOOKUP(A18,'Leghe Fantacalcio'!A:I,2,FALSE)) -> 7626 | M18: =IF(ISNA(VLOOKUP(B18,'Leghe Fantacalcio'!A:I,2,FALSE)),"",VLOOKUP(B18,'Leghe Fantacalcio'!A:I,2,FALSE)) | N18: =IFERROR(VALUE(CONCATENATE(L18,M18)),"") -> 7626 | O18: =IFERROR(VLOOKUP(N18,'Leghe Fantacalcio'!B:I,8,FALSE),0) -> 1 | P18: =CONCATENATE("update giocatori set fvm = ",O18," where id = ",C18,";") -> update giocatori set fvm = 1 where id = 1120636;
... A42: =CONCATENATE(D42,F42) -> HolmBologna | B42: =CONCATENATE(D42," ",E42,F42) -> Holm E.Bologna | C42: 1098169 | D42: Holm | E42: E. | F42: Bologna | G42: D | H42: 6 | I42: 12 | J42: =VLOOKUP(A42,'Leghe Fantacalcio'!A:I,1,FALSE) -> HolmBologna | K42: =VLOOKUP(B42,'Leghe Fantacalcio'!A:I,1,FALSE) -> #N/A | L42: =IF(ISNA(VLOOKUP(A42,'Leghe Fantacalcio'!A:I,2,FALSE)),"",VLOOKUP(A42,'Leghe Fantacalcio'!A:I,2,FALSE)) -> 5678 | M42: =IF(ISNA(VLOOKUP(B42,'Leghe Fantacalcio'!A:I,2,FALSE)),"",VLOOKUP(B42,'Leghe Fantacalcio'!A:I,2,FALSE)) | N42: =IFERROR(VALUE(CONCATENATE(L42,M42)),"") -> 5678 | O42: =IFERROR(VLOOKUP(N42,'Leghe Fantacalcio'!B:I,8,FALSE),0) -> 11 | P42: =CONCATENATE("update giocatori set fvm = ",O42," where id = ",C42,";") -> update giocatori set fvm = 11 where id = 1098169;
A43: =CONCATENATE(D43,F43) -> Miranda J.Bologna | B43: =CONCATENATE(D43," ",E43,F43) -> Miranda J. Bologna | C43: 1066177 | D43: Miranda J. | F43: Bologna | G43: D | H43: 6 | I43: 14 | J43: =VLOOKUP(A43,'Leghe Fantacalcio'!A:I,1,FALSE) -> Miranda J.Bologna | K43: =VLOOKUP(B43,'Leghe Fantacalcio'!A:I,1,FALSE) -> #N/A | L43: =IF(ISNA(VLOOKUP(A43,'Leghe Fantacalcio'!A:I,2,FALSE)),"",VLOOKUP(A43,'Leghe Fantacalcio'!A:I,2,FALSE)) -> 4734 | M43: =IF(ISNA(VLOOKUP(B43,'Leghe Fantacalcio'!A:I,2,FALSE)),"",VLOOKUP(B43,'Leghe Fantacalcio'!A:I,2,FALSE)) | N43: =IFERROR(VALUE(CONCATENATE(L43,M43)),"") -> 4734 | O43: =IFERROR(VLOOKUP(N43,'Leghe Fantacalcio'!B:I,8,FALSE),0) -> 22 | P43: =CONCATENATE("update giocatori set fvm = ",O43," where id = ",C43,";") -> update giocatori set fvm = 22 where id = 1066177;
A44: =CONCATENATE(D44,F44) -> MbangulaBologna | B44: =CONCATENATE(D44," ",E44,F44) -> Mbangula S.Bologna | C44: 1119754 | D44: Mbangula | E44: S. | F44: Bologna | G44: C | H44: 6 | I44: 17 | J44: =VLOOKUP(A44,'Leghe Fantacalcio'!A:I,1,FALSE) -> MbangulaBologna | K44: =VLOOKUP(B44,'Leghe Fantacalcio'!A:I,1,FALSE) -> #N/A | L44: =IF(ISNA(VLOOKUP(A44,'Leghe Fantacalcio'!A:I,2,FALSE)),"",VLOOKUP(A44,'Leghe Fantacalcio'!A:I,2,FALSE)) -> 6833 | M44: =IF(ISNA(VLOOKUP(B44,'Leghe Fantacalcio'!A:I,2,FALSE)),"",VLOOKUP(B44,'Leghe Fantacalcio'!A:I,2,FALSE)) | N44: =IFERROR(VALUE(CONCATENATE(L44,M44)),"") -> 6833 | O44: =IFERROR(VLOOKUP(N44,'Leghe Fantacalcio'!B:I,8,FALSE),0) -> 16 | P44: =CONCATENATE("update giocatori set fvm = ",O44," where id = ",C44,";") -> update giocatori set fvm = 16 where id = 1119754;
A45: =CONCATENATE(D45,F45) -> MoroBologna | B45: =CONCATENATE(D45," ",E45,F45) -> Moro N.Bologna | C45: 1052254 | D45: Moro | E45: N. | F45: Bologna | G45: C | H45: 6 | I45: 17 | J45: =VLOOKUP(A45,'Leghe Fantacalcio'!A:I,1,FALSE) -> #N/A | K45: =VLOOKUP(B45,'Leghe Fantacalcio'!A:I,1,FALSE) -> Moro N.Bologna | L45: =IF(ISNA(VLOOKUP(A45,'Leghe Fantacalcio'!A:I,2,FALSE)),"",VLOOKUP(A45,'Leghe Fantacalcio'!A:I,2,FALSE)) | M45: =IF(ISNA(VLOOKUP(B45,'Leghe Fantacalcio'!A:I,2,FALSE)),"",VLOOKUP(B45,'Leghe Fantacalcio'!A:I,2,FALSE)) -> 6054 | N45: =IFERROR(VALUE(CONCATENATE(L45,M45)),"") -> 6054 | O45: =IFERROR(VLOOKUP(N45,'Leghe Fantacalcio'!B:I,8,FALSE),0) -> 14 | P45: =CONCATENATE("update giocatori set fvm = ",O45," where id = ",C45,";") -> update giocatori set fvm = 14 where id = 1052254;
A46: =CONCATENATE(D46,F46) -> OdgaardBologna | B46: =CONCATENATE(D46," ",E46,F46) -> Odgaard J.Bologna | C46: 1102014 | D46: Odgaard | E46: J. | F46: Bologna | G46: C | H46: 6 | I46: 19 | J46: =VLOOKUP(A46,'Leghe Fantacalcio'!A:I,1,FALSE) -> OdgaardBologna | K46: =VLOOKUP(B46,'Leghe Fantacalcio'!A:I,1,FALSE) -> #N/A | L46: =IF(ISNA(VLOOKUP(A46,'Leghe Fantacalcio'!A:I,2,FALSE)),"",VLOOKUP(A46,'Leghe Fantacalcio'!A:I,2,FALSE)) -> 2765 | M46: =IF(ISNA(VLOOKUP(B46,'Leghe Fantacalcio'!A:I,2,FALSE)),"",VLOOKUP(B46,'Leghe Fantacalcio'!A:I,2,FALSE)) | N46: =IFERROR(VALUE(CONCATENATE(L46,M46)),"") -> 2765 | O46: =IFERROR(VLOOKUP(N46,'Leghe Fantacalcio'!B:I,8,FALSE),0) -> 13 | P46: =CONCATENATE("update giocatori set fvm = ",O46," where id = ",C46,";") -> update giocatori set fvm = 13 where id = 1102014;
A47: =CONCATENATE(D47,F47) -> OrsoliniBologna | B47: =CONCATENATE(D47," ",E47,F47) -> Orsolini R.Bologna | C47: 1052468 | D47: Orsolini | E47: R. | F47: Bologna | G47: C | H47: 6 | I47: 34 | J47: =VLOOKUP(A47,'Leghe Fantacalcio'!A:I,1,FALSE) -> OrsoliniBologna | K47: =VLOOKUP(B47,'Leghe Fantacalcio'!A:I,1,FALSE) -> #N/A | L47: =IF(ISNA(VLOOKUP(A47,'Leghe Fantacalcio'!A:I,2,FALSE)),"",VLOOKUP(A47,'Leghe Fantacalcio'!A:I,2,FALSE)) -> 2167 | M47: =IF(ISNA(VLOOKUP(B47,'Leghe Fantacalcio'!A:I,2,FALSE)),"",VLOOKUP(B47,'Leghe Fantacalcio'!A:I,2,FALSE)) | N47: =IFERROR(VALUE(CONCATENATE(L47,M47)),"") -> 2167 | O47: =IFERROR(VLOOKUP(N47,'Leghe Fantacalcio'!B:I,8,FALSE),0) -> 138 | P47: =CONCATENATE("update giocatori set fvm = ",O47," where id = ",C47,";") -> update giocatori set fvm = 138 where id = 1052468;
A48: =CONCATENATE(D48,F48) -> PessinaBologna | B48: =CONCATENATE(D48," ",E48,F48) -> Pessina M.Bologna | C48: 1119794 | D48: Pessina | E48: M. | F48: Bologna | G48: P | H48: 6 | I48: 2 | J48: =VLOOKUP(A48,'Leghe Fantacalcio'!A:I,1,FALSE) -> #N/A | K48: =VLOOKUP(B48,'Leghe Fantacalcio'!A:I,1,FALSE) -> #N/A | L48: =IF(ISNA(VLOOKUP(A48,'Leghe Fantacalcio'!A:I,2,FALSE)),"",VLOOKUP(A48,'Leghe Fantacalcio'!A:I,2,FALSE)) | M48: =IF(ISNA(VLOOKUP(B48,'Leghe Fantacalcio'!A:I,2,FALSE)),"",VLOOKUP(B48,'Leghe Fantacalcio'!A:I,2,FALSE)) | N48: =IFERROR(VALUE(CONCATENATE(L48,M48)),"") | O48: =IFERROR(VLOOKUP(N48,'Leghe Fantacalcio'!B:I,8,FALSE),0) -> 0 | P48: =CONCATENATE("update giocatori set fvm = ",O48," where id = ",C48,";") -> update giocatori set fvm = 0 where id = 1119794;
A49: =CONCATENATE(D49,F49) -> PiccoliBologna | B49: =CONCATENATE(D49," ",E49,F49) -> Piccoli R.Bologna | C49: 1070458 | D49: Piccoli | E49: R. | F49: Bologna | G49: A | H49: 6 | I49: 24 | J49: =VLOOKUP(A49,'Leghe Fantacalcio'!A:I,1,FALSE) -> PiccoliBologna | K49: =VLOOKUP(B49,'Leghe Fantacalcio'!A:I,1,FALSE) -> #N/A | L49: =IF(ISNA(VLOOKUP(A49,'Leghe Fantacalcio'!A:I,2,FALSE)),"",VLOOKUP(A49,'Leghe Fantacalcio'!A:I,2,FALSE)) -> 4359 | M49: =IF(ISNA(VLOOKUP(B49,'Leghe Fantacalcio'!A:I,2,FALSE)),"",VLOOKUP(B49,'Leghe Fantacalcio'!A:I,2,FALSE)) | N49: =IFERROR(VALUE(CONCATENATE(L49,M49)),"") -> 4359 | O49: =IFERROR(VLOOKUP(N49,'Leghe Fantacalcio'!B:I,8,FALSE),0) -> 41 | P49: =CONCATENATE("update giocatori set fvm = ",O49," where id = ",C49,";") -> update giocatori set fvm = 41 where id = 1070458;
A50: =CONCATENATE(D50,F50) -> PobegaBologna | B50: =CONCATENATE(D50," ",E50,F50) -> Pobega T.Bologna | C50: 1060968 | D50: Pobega | E50: T. | F50: Bologna | G50: C | H50: 6 | I50: 18 | J50: =VLOOKUP(A50,'Leghe Fantacalcio'!A:I,1,FALSE) -> PobegaBologna | K50: =VLOOKUP(B50,'Leghe Fantacalcio'!A:I,1,FALSE) -> #N/A | L50: =IF(ISNA(VLOOKUP(A50,'Leghe Fantacalcio'!A:I,2,FALSE)),"",VLOOKUP(A50,'Leghe Fantacalcio'!A:I,2,FALSE)) -> 5298 | M50: =IF(ISNA(VLOOKUP(B50,'Leghe Fantacalcio'!A:I,2,FALSE)),"",VLOOKUP(B50,'Leghe Fantacalcio'!A:I,2,FALSE)) | N50: =IFERROR(VALUE(CONCATENATE(L50,M50)),"") -> 5298 | O50: =IFERROR(VLOOKUP(N50,'Leghe Fantacalcio'!B:I,8,FALSE),0) -> 12 | P50: =CONCATENATE("update giocatori set fvm = ",O50," where id = ",C50,";") -> update giocatori set fvm = 12 where id = 1060968;
A51: =CONCATENATE(D51,F51) -> SkorupskiBologna | B51: =CONCATENATE(D51," ",E51,F51) -> Skorupski L.Bologna | C51: 1038871 | D51: Skorupski | E51: L. | F51: Bologna | G51: P | H51: 6 | I51: 11 | J51: =VLOOKUP(A51,'Leghe Fantacalcio'!A:I,1,FALSE) -> SkorupskiBologna | K51: =VLOOKUP(B51,'Leghe Fantacalcio'!A:I,1,FALSE) -> #N/A | L51: =IF(ISNA(VLOOKUP(A51,'Leghe Fantacalcio'!A:I,2,FALSE)),"",VLOOKUP(A51,'Leghe Fantacalcio'!A:I,2,FALSE)) -> 133 | M51: =IF(ISNA(VLOOKUP(B51,'Leghe Fantacalcio'!A:I,2,FALSE)),"",VLOOKUP(B51,'Leghe Fantacalcio'!A:I,2,FALSE)) | N51: =IFERROR(VALUE(CONCATENATE(L51,M51)),"") -> 133 | O51: =IFERROR(VLOOKUP(N51,'Leghe Fantacalcio'!B:I,8,FALSE),0) -> 23 | P51: =CONCATENATE("update giocatori set fvm = ",O51," where id = ",C51,";") -> update giocatori set fvm = 23 where id = 1038871;
A52: =CONCATENATE(D52,F52) -> TheateBologna | B52: =CONCATENATE(D52," ",E52,F52) -> Theate A.Bologna | C52: 1110749 | D52: Theate | E52: A. | F52: Bologna | G52: D | H52: 6 | I52: 20 | J52: =VLOOKUP(A52,'Leghe Fantacalcio'!A:I,1,FALSE) -> TheateBologna | K52: =VLOOKUP(B52,'Leghe Fantacalcio'!A:I,1,FALSE) -> #N/A | L52: =IF(ISNA(VLOOKUP(A52,'Leghe Fantacalcio'!A:I,2,FALSE)),"",VLOOKUP(A52,'Leghe Fantacalcio'!A:I,2,FALSE)) -> 5675 | M52: =IF(ISNA(VLOOKUP(B52,'Leghe Fantacalcio'!A:I,2,FALSE)),"",VLOOKUP(B52,'Leghe Fantacalcio'!A:I,2,FALSE)) | N52: =IFERROR(VALUE(CONCATENATE(L52,M52)),"") -> 5675 | O52: =IFERROR(VLOOKUP(N52,'Leghe Fantacalcio'!B:I,8,FALSE),0) -> 20 | P52: =CONCATENATE("update giocatori set fvm = ",O52," where id = ",C52,";") -> update giocatori set fvm = 20 where id = 1110749;
A53: =CONCATENATE(D53,F53) -> VitikBologna | B53: =CONCATENATE(D53," ",E53,F53) -> Vitik M.Bologna | C53: 1102743 | D53: Vitik | E53: M. | F53: Bologna | G53: D | H53: 6 | I53: 4 | J53: =VLOOKUP(A53,'Leghe Fantacalcio'!A:I,1,FALSE) -> VitikBologna | K53: =VLOOKUP(B53,'Leghe Fantacalcio'!A:I,1,FALSE) -> #N/A | L53: =IF(ISNA(VLOOKUP(A53,'Leghe Fantacalcio'!A:I,2,FALSE)),"",VLOOKUP(A53,'Leghe Fantacalcio'!A:I,2,FALSE)) -> 7068 | M53: =IF(ISNA(VLOOKUP(B53,'Leghe Fantacalcio'!A:I,2,FALSE)),"",VLOOKUP(B53,'Leghe Fantacalcio'!A:I,2,FALSE)) | N53: =IFERROR(VALUE(CONCATENATE(L53,M53)),"") -> 7068 | O53: =IFERROR(VLOOKUP(N53,'Leghe Fantacalcio'!B:I,8,FALSE),0) -> 9 | P53: =CONCATENATE("update giocatori set fvm = ",O53," where id = ",C53,";") -> update giocatori set fvm = 9 where id = 1102743;
A54: =CONCATENATE(D54,F54) -> ZorteaBologna | B54: =CONCATENATE(D54," ",E54,F54) -> Zortea N.Bologna | C54: 1076574 | D54: Zortea | E54: N. | F54: Bologna | G54: D | H54: 6 | I54: 9 | J54: =VLOOKUP(A54,'Leghe Fantacalcio'!A:I,1,FALSE) -> ZorteaBologna | K54: =VLOOKUP(B54,'Leghe Fantacalcio'!A:I,1,FALSE) -> #N/A | L54: =IF(ISNA(VLOOKUP(A54,'Leghe Fantacalcio'!A:I,2,FALSE)),"",VLOOKUP(A54,'Leghe Fantacalcio'!A:I,2,FALSE)) -> 4433 | M54: =IF(ISNA(VLOOKUP(B54,'Leghe Fantacalcio'!A:I,2,FALSE)),"",VLOOKUP(B54,'Leghe Fantacalcio'!A:I,2,FALSE)) | N54: =IFERROR(VALUE(CONCATENATE(L54,M54)),"") -> 4433 | O54: =IFERROR(VLOOKUP(N54,'Leghe Fantacalcio'!B:I,8,FALSE),0) -> 17 | P54: =CONCATENATE("update giocatori set fvm = ",O54," where id = ",C54,";") -> update giocatori set fvm = 17 where id = 1076574;
A55: =CONCATENATE(D55,F55) -> AdopoCagliari | B55: =CONCATENATE(D55," ",E55,F55) -> Adopo M.Cagliari | C55: 1066457 | D55: Adopo | E55: M. | F55: Cagliari | G55: C | H55: 6 | I55: 18 | J55: =VLOOKUP(A55,'Leghe Fantacalcio'!A:I,1,FALSE) -> AdopoCagliari | K55: =VLOOKUP(B55,'Leghe Fantacalcio'!A:I,1,FALSE) -> #N/A | L55: =IF(ISNA(VLOOKUP(A55,'Leghe Fantacalcio'!A:I,2,FALSE)),"",VLOOKUP(A55,'Leghe Fantacalcio'!A:I,2,FALSE)) -> 4870 | M55: =IF(ISNA(VLOOKUP(B55,'Leghe Fantacalcio'!A:I,2,FALSE)),"",VLOOKUP(B55,'Leghe Fantacalcio'!A:I,2,FALSE)) | N55: =IFERROR(VALUE(CONCATENATE(L55,M55)),"") -> 4870 | O55: =IFERROR(VLOOKUP(N55,'Leghe Fantacalcio'!B:I,8,FALSE),0) -> 12 | P55: =CONCATENATE("update giocatori set fvm = ",O55," where id = ",C55,";") -> update giocatori set fvm = 12 where id = 1066457;
... A66: =CONCATENATE(D66,F66) -> IdrissiCagliari | B66: =CONCATENATE(D66," ",E66,F66) -> Idrissi R.Cagliari | C66: 1119938 | D66: Idrissi | E66: R. | F66: Cagliari | G66: D | H66: 6 | I66: 3 | J66: =VLOOKUP(A66,'Leghe Fantacalcio'!A:I,1,FALSE) -> #N/A | K66: =VLOOKUP(B66,'Leghe Fantacalcio'!A:I,1,FALSE) -> Idrissi R.Cagliari | L66: =IF(ISNA(VLOOKUP(A66,'Leghe Fantacalcio'!A:I,2,FALSE)),"",VLOOKUP(A66,'Leghe Fantacalcio'!A:I,2,FALSE)) | M66: =IF(ISNA(VLOOKUP(B66,'Leghe Fantacalcio'!A:I,2,FALSE)),"",VLOOKUP(B66,'Leghe Fantacalcio'!A:I,2,FALSE)) -> 7125 | N66: =IFERROR(VALUE(CONCATENATE(L66,M66)),"") -> 7125 | O66: =IFERROR(VLOOKUP(N66,'Leghe Fantacalcio'!B:I,8,FALSE),0) -> 3 | P66: =CONCATENATE("update giocatori set fvm = ",O66," where id = ",C66,";") -> update giocatori set fvm = 3 where id = 1119938;
A67: =CONCATENATE(D67,F67) -> Kevin CarlosCagliari | B67: =CONCATENATE(D67," ",E67,F67) -> Kevin Carlos Cagliari | C67: 1103519 | D67: Kevin Carlos | F67: Cagliari | G67: A | H67: 6 | I67: 9 | J67: =VLOOKUP(A67,'Leghe Fantacalcio'!A:I,1,FALSE) -> Kevin CarlosCagliari | K67: =VLOOKUP(B67,'Leghe Fantacalcio'!A:I,1,FALSE) -> #N/A | L67: =IF(ISNA(VLOOKUP(A67,'Leghe Fantacalcio'!A:I,2,FALSE)),"",VLOOKUP(A67,'Leghe Fantacalcio'!A:I,2,FALSE)) -> 7547 | M67: =IF(ISNA(VLOOKUP(B67,'Leghe Fantacalcio'!A:I,2,FALSE)),"",VLOOKUP(B67,'Leghe Fantacalcio'!A:I,2,FALSE)) | N67: =IFERROR(VALUE(CONCATENATE(L67,M67)),"") -> 7547 | O67: =IFERROR(VLOOKUP(N67,'Leghe Fantacalcio'!B:I,8,FALSE),0) -> 20 | P67: =CONCATENATE("update giocatori set fvm = ",O67," where id = ",C67,";") -> update giocatori set fvm = 20 where id = 1103519;
A68: =CONCATENATE(D68,F68) -> KoflerCagliari | B68: =CONCATENATE(D68," ",E68,F68) -> Kofler R.Cagliari | C68: 1115107 | D68: Kofler | E68: R. | F68: Cagliari | G68: D | H68: 6 | I68: 2 | J68: =VLOOKUP(A68,'Leghe Fantacalcio'!A:I,1,FALSE) -> KoflerCagliari | K68: =VLOOKUP(B68,'Leghe Fantacalcio'!A:I,1,FALSE) -> #N/A | L68: =IF(ISNA(VLOOKUP(A68,'Leghe Fantacalcio'!A:I,2,FALSE)),"",VLOOKUP(A68,'Leghe Fantacalcio'!A:I,2,FALSE)) -> 7532 | M68: =IF(ISNA(VLOOKUP(B68,'Leghe Fantacalcio'!A:I,2,FALSE)),"",VLOOKUP(B68,'Leghe Fantacalcio'!A:I,2,FALSE)) | N68: =IFERROR(VALUE(CONCATENATE(L68,M68)),"") -> 7532 | O68: =IFERROR(VLOOKUP(N68,'Leghe Fantacalcio'!B:I,8,FALSE),0) -> 4 | P68: =CONCATENATE("update giocatori set fvm = ",O68," where id = ",C68,";") -> update giocatori set fvm = 4 where id = 1115107;
A69: =CONCATENATE(D69,F69) -> LitetaCagliari | B69: =CONCATENATE(D69," ",E69,F69) -> Liteta J.Cagliari | C69: 1119941 | D69: Liteta | E69: J. | F69: Cagliari | G69: C | H69: 6 | I69: 1 | J69: =VLOOKUP(A69,'Leghe Fantacalcio'!A:I,1,FALSE) -> LitetaCagliari | K69: =VLOOKUP(B69,'Leghe Fantacalcio'!A:I,1,FALSE) -> #N/A | L69: =IF(ISNA(VLOOKUP(A69,'Leghe Fantacalcio'!A:I,2,FALSE)),"",VLOOKUP(A69,'Leghe Fantacalcio'!A:I,2,FALSE)) -> 7165 | M69: =IF(ISNA(VLOOKUP(B69,'Leghe Fantacalcio'!A:I,2,FALSE)),"",VLOOKUP(B69,'Leghe Fantacalcio'!A:I,2,FALSE)) | N69: =IFERROR(VALUE(CONCATENATE(L69,M69)),"") -> 7165 | O69: =IFERROR(VLOOKUP(N69,'Leghe Fantacalcio'!B:I,8,FALSE),0) -> 1 | P69: =CONCATENATE("update giocatori set fvm = ",O69," where id = ",C69,";") -> update giocatori set fvm = 1 where id = 1119941;
A70: =CONCATENATE(D70,F70) -> MaldiniCagliari | B70: =CONCATENATE(D70," ",E70,F70) -> Maldini D.Cagliari | C70: 1073082 | D70: Maldini | E70: D. | F70: Cagliari | G70: C | H70: 6 | I70: 26 | J70: =VLOOKUP(A70,'Leghe Fantacalcio'!A:I,1,FALSE) -> MaldiniCagliari | K70: =VLOOKUP(B70,'Leghe Fantacalcio'!A:I,1,FALSE) -> #N/A | L70: =IF(ISNA(VLOOKUP(A70,'Leghe Fantacalcio'!A:I,2,FALSE)),"",VLOOKUP(A70,'Leghe Fantacalcio'!A:I,2,FALSE)) -> 4896 | M70: =IF(ISNA(VLOOKUP(B70,'Leghe Fantacalcio'!A:I,2,FALSE)),"",VLOOKUP(B70,'Leghe Fantacalcio'!A:I,2,FALSE)) | N70: =IFERROR(VALUE(CONCATENATE(L70,M70)),"") -> 4896 | O70: =IFERROR(VLOOKUP(N70,'Leghe Fantacalcio'!B:I,8,FALSE),0) -> 45 | P70: =CONCATENATE("update giocatori set fvm = ",O70," where id = ",C70,";") -> update giocatori set fvm = 45 where id = 1073082;
A71: =CONCATENATE(D71,F71) -> MassolinCagliari | B71: =CONCATENATE(D71," ",E71,F71) -> Massolin Y.Cagliari | C71: 1113542 | D71: Massolin | E71: Y. | F71: Cagliari | G71: C | H71: 6 | I71: 2 | J71: =VLOOKUP(A71,'Leghe Fantacalcio'!A:I,1,FALSE) -> MassolinCagliari | K71: =VLOOKUP(B71,'Leghe Fantacalcio'!A:I,1,FALSE) -> #N/A | L71: =IF(ISNA(VLOOKUP(A71,'Leghe Fantacalcio'!A:I,2,FALSE)),"",VLOOKUP(A71,'Leghe Fantacalcio'!A:I,2,FALSE)) -> 7579 | M71: =IF(ISNA(VLOOKUP(B71,'Leghe Fantacalcio'!A:I,2,FALSE)),"",VLOOKUP(B71,'Leghe Fantacalcio'!A:I,2,FALSE)) | N71: =IFERROR(VALUE(CONCATENATE(L71,M71)),"") -> 7579 | O71: =IFERROR(VLOOKUP(N71,'Leghe Fantacalcio'!B:I,8,FALSE),0) -> 12 | P71: =CONCATENATE("update giocatori set fvm = ",O71," where id = ",C71,";") -> update giocatori set fvm = 12 where id = 1113542;
A72: =CONCATENATE(D72,F72) -> NzolaCagliari | B72: =CONCATENATE(D72," ",E72,F72) -> Nzola Cagliari | C72: 1064600 | D72: Nzola | F72: Cagliari | G72: A | H72: 6 | I72: 13 | J72: =VLOOKUP(A72,'Leghe Fantacalcio'!A:I,1,FALSE) -> NzolaCagliari | K72: =VLOOKUP(B72,'Leghe Fantacalcio'!A:I,1,FALSE) -> #N/A | L72: =IF(ISNA(VLOOKUP(A72,'Leghe Fantacalcio'!A:I,2,FALSE)),"",VLOOKUP(A72,'Leghe Fantacalcio'!A:I,2,FALSE)) -> 5336 | M72: =IF(ISNA(VLOOKUP(B72,'Leghe Fantacalcio'!A:I,2,FALSE)),"",VLOOKUP(B72,'Leghe Fantacalcio'!A:I,2,FALSE)) | N72: =IFERROR(VALUE(CONCATENATE(L72,M72)),"") -> 5336 | O72: =IFERROR(VLOOKUP(N72,'Leghe Fantacalcio'!B:I,8,FALSE),0) -> 10 | P72: =CONCATENATE("update giocatori set fvm = ",O72," where id = ",C72,";") -> update giocatori set fvm = 10 where id = 1064600;
A73: =CONCATENATE(D73,F73) -> MendyCagliari | B73: =CONCATENATE(D73," ",E73,F73) -> Mendy P.Cagliari | C73: 1120334 | D73: Mendy | E73: P. | F73: Cagliari | G73: A | H73: 6 | I73: 7 | J73: =VLOOKUP(A73,'Leghe Fantacalcio'!A:I,1,FALSE) -> #N/A | K73: =VLOOKUP(B73,'Leghe Fantacalcio'!A:I,1,FALSE) -> Mendy P.Cagliari | L73: =IF(ISNA(VLOOKUP(A73,'Leghe Fantacalcio'!A:I,2,FALSE)),"",VLOOKUP(A73,'Leghe Fantacalcio'!A:I,2,FALSE)) | M73: =IF(ISNA(VLOOKUP(B73,'Leghe Fantacalcio'!A:I,2,FALSE)),"",VLOOKUP(B73,'Leghe Fantacalcio'!A:I,2,FALSE)) -> 7374 | N73: =IFERROR(VALUE(CONCATENATE(L73,M73)),"") -> 7374 | O73: =IFERROR(VLOOKUP(N73,'Leghe Fantacalcio'!B:I,8,FALSE),0) -> 20 | P73: =CONCATENATE("update giocatori set fvm = ",O73," where id = ",C73,";") -> update giocatori set fvm = 20 where id = 1120334;
...

Sheet Leghe Fantacalcio
A1: NomeSquadra | B1: Id | C1: R | D1: Nome | E1: Squadra | F1: Qt.A | G1: Qt.I | H1: Diff. | I1: FVM | J1: Trovato
A2: =CONCATENATE(D2,E2) -> BellanovaAtalanta | B2: 4887 | C2: D | D2: Bellanova | E2: Atalanta | F2: 5 | G2: 6 | H2: -1 | I2: 16 | J2: =VLOOKUP(B2,'Quotazioni calciatori'!N:N,1,FALSE) -> 4887
A3: =CONCATENATE(D3,E3) -> BernasconiAtalanta | B3: 7219 | C3: D | D3: Bernasconi | E3: Atalanta | F3: 5 | G3: 6 | H3: -1 | I3: 14 | J3: =VLOOKUP(B3,'Quotazioni calciatori'!N:N,1,FALSE) -> 7219
A4: =CONCATENATE(D4,E4) -> CarnesecchiAtalanta | B4: 4431 | C4: P | D4: Carnesecchi | E4: Atalanta | F4: 16 | G4: 16 | H4: 0 | I4: 56 | J4: =VLOOKUP(B4,'Quotazioni calciatori'!N:N,1,FALSE) -> 4431
A5: =CONCATENATE(D5,E5) -> De KetelaereAtalanta | B5: 5995 | C5: A | D5: De Ketelaere | E5: Atalanta | F5: 15 | G5: 17 | H5: -2 | I5: 64 | J5: =VLOOKUP(B5,'Quotazioni calciatori'!N:N,1,FALSE) -> 5995
A6: =CONCATENATE(D6,E6) -> Ederson D.S.Atalanta | B6: 5792 | C6: C | D6: Ederson D.S. | E6: Atalanta | F6: 13 | G6: 12 | H6: 1 | I6: 45 | J6: =VLOOKUP(B6,'Quotazioni calciatori'!N:N,1,FALSE) -> 5792
A7: =CONCATENATE(D7,E7) -> ElmasAtalanta | B7: 4479 | C7: C | D7: Elmas | E7: Atalanta | F7: 6 | G7: 7 | H7: -1 | I7: 17 | J7: =VLOOKUP(B7,'Quotazioni calciatori'!N:N,1,FALSE) -> 4479
A8: =CONCATENATE(D8,E8) -> GaetanoAtalanta | B8: 4364 | C8: C | D8: Gaetano | E8: Atalanta | F8: 6 | G8: 7 | H8: -1 | I8: 23 | J8: =VLOOKUP(B8,'Quotazioni calciatori'!N:N,1,FALSE) -> 4364
A9: =CONCATENATE(D9,E9) -> HienAtalanta | B9: 6046 | C9: D | D9: Hien | E9: Atalanta | F9: 6 | G9: 8 | H9: -2 | I9: 10 | J9: =VLOOKUP(B9,'Quotazioni calciatori'!N:N,1,FALSE) -> 6046
A10: =CONCATENATE(D10,E10) -> KessièAtalanta | B10: 1850 | C10: C | D10: Kessiè | E10: Atalanta | F10: 11 | G10: 12 | H10: -1 | I10: 33 | J10: =VLOOKUP(B10,'Quotazioni calciatori'!N:N,1,FALSE) -> 1850
A11: =CONCATENATE(D11,E11) -> KolasinacAtalanta | B11: 2640 | C11: D | D11: Kolasinac | E11: Atalanta | F11: 6 | G11: 5 | H11: 1 | I11: 11 | J11: =VLOOKUP(B11,'Quotazioni calciatori'!N:N,1,FALSE) -> 2640
A12: =CONCATENATE(D12,E12) -> KossounouAtalanta | B12: 5578 | C12: D | D12: Kossounou | E12: Atalanta | F12: 3 | G12: 3 | H12: 0 | I12: 12 | J12: =VLOOKUP(B12,'Quotazioni calciatori'!N:N,1,FALSE) -> 5578
A13: =CONCATENATE(D13,E13) -> Kristensen T.Atalanta | B13: 6485 | C13: D | D13: Kristensen T. | E13: Atalanta | F13: 5 | G13: 7 | H13: -2 | I13: 14 | J13: =VLOOKUP(B13,'Quotazioni calciatori'!N:N,1,FALSE) -> 6485
... A535: =CONCATENATE(D535,E535) -> Yeboah J.Venezia | B535: 6904 | C535: A | D535: Yeboah J. | E535: Venezia | F535: 8 | G535: 8 | H535: 0 | I535: 27 | J535: =VLOOKUP(B535,'Quotazioni calciatori'!N:N,1,FALSE) -> 6904

Sheet Foglio1
A1: id fs | B1: nome fs | C1: sq | D1: id fg | E1: nome fg | F1: cambiare
A2: 118370 | B2: lucas perri | C2: Tor | D2: =VLOOKUP(1000000+A2,'Quotazioni calciatori'!C:N,12,FALSE) -> 6534 | E2: =VLOOKUP(D2,'Leghe Fantacalcio'!B:D,3,FALSE) -> Perri | F2: =EXACT(UPPER(B2),UPPER(E2)) -> FALSE | G2: =IF(F2,"",CONCATENATE("if (giocatore.getSquadra().equalsIgnoreCase(""",C2,""") && giocatore.getNomeFS().equalsIgnoreCase(""",B2,""")) giocatore.setNomeFSCambiato(""",E2,""");")) -> if (giocatore.getSquadra().equalsIgnoreCase("Tor") && giocatore.getNomeFS().equalsIgnoreCase("lucas perri")) giocatore.setNomeFSCambiato("Perri");
A3: 67789 | B3: bremer | C3: Juv | D3: =VLOOKUP(1000000+A3,'Quotazioni calciatori'!C:N,12,FALSE) -> 2788 | E3: =VLOOKUP(D3,'Leghe Fantacalcio'!B:D,3,FALSE) -> Bremer | F3: =EXACT(UPPER(B3),UPPER(E3)) -> TRUE | G3: =IF(F3,"",CONCATENATE("if (giocatore.getSquadra().equalsIgnoreCase(""",C3,""") && giocatore.getNomeFS().equalsIgnoreCase(""",B3,""")) giocatore.setNomeFSCambiato(""",E3,""");"))
A4: 49438 | B4: mancini | C4: Rom | D4: =VLOOKUP(1000000+A4,'Quotazioni calciatori'!C:N,12,FALSE) -> 2296 | E4: =VLOOKUP(D4,'Leghe Fantacalcio'!B:D,3,FALSE) -> Mancini | F4: =EXACT(UPPER(B4),UPPER(E4)) -> TRUE | G4: =IF(F4,"",CONCATENATE("if (giocatore.getSquadra().equalsIgnoreCase(""",C4,""") && giocatore.getNomeFS().equalsIgnoreCase(""",B4,""")) giocatore.setNomeFSCambiato(""",E4,""");"))
A5: 94914 | B5: yan couto | C5: Com | D5: =VLOOKUP(1000000+A5,'Quotazioni calciatori'!C:N,12,FALSE) -> 6727 | E5: =VLOOKUP(D5,'Leghe Fantacalcio'!B:D,3,FALSE) -> Couto | F5: =EXACT(UPPER(B5),UPPER(E5)) -> FALSE | G5: =IF(F5,"",CONCATENATE("if (giocatore.getSquadra().equalsIgnoreCase(""",C5,""") && giocatore.getNomeFS().equalsIgnoreCase(""",B5,""")) giocatore.setNomeFSCambiato(""",E5,""");")) -> if (giocatore.getSquadra().equalsIgnoreCase("Com") && giocatore.getNomeFS().equalsIgnoreCase("yan couto")) giocatore.setNomeFSCambiato("Couto");
A6: 102062 | B6: valeri | C6: Par | D6: =VLOOKUP(1000000+A6,'Quotazioni calciatori'!C:N,12,FALSE) -> 5862 | E6: =VLOOKUP(D6,'Leghe Fantacalcio'!B:D,3,FALSE) -> Valeri | F6: =EXACT(UPPER(B6),UPPER(E6)) -> TRUE | G6: =IF(F6,"",CONCATENATE("if (giocatore.getSquadra().equalsIgnoreCase(""",C6,""") && giocatore.getNomeFS().equalsIgnoreCase(""",B6,""")) giocatore.setNomeFSCambiato(""",E6,""");"))
A7: 104526 | B7: francisco conceicao | C7: Juv | D7: =VLOOKUP(1000000+A7,'Quotazioni calciatori'!C:N,12,FALSE) -> 6884 | E7: =VLOOKUP(D7,'Leghe Fantacalcio'!B:D,3,FALSE) -> Conceicao | F7: =EXACT(UPPER(B7),UPPER(E7)) -> FALSE | G7: =IF(F7,"",CONCATENATE("if (giocatore.getSquadra().equalsIgnoreCase(""",C7,""") && giocatore.getNomeFS().equalsIgnoreCase(""",B7,""")) giocatore.setNomeFSCambiato(""",E7,""");")) -> if (giocatore.getSquadra().equalsIgnoreCase("Juv") && giocatore.getNomeFS().equalsIgnoreCase("francisco conceicao")) giocatore.setNomeFSCambiato("Conceicao");
A8: 19157 | B8: de bruyne | C8: Nap | D8: =VLOOKUP(1000000+A8,'Quotazioni calciatori'!C:N,12,FALSE) -> 2517 | E8: =VLOOKUP(D8,'Leghe Fantacalcio'!B:D,3,FALSE) -> De Bruyne | F8: =EXACT(UPPER(B8),UPPER(E8)) -> TRUE | G8: =IF(F8,"",CONCATENATE("if (giocatore.getSquadra().equalsIgnoreCase(""",C8,""") && giocatore.getNomeFS().equalsIgnoreCase(""",B8,""")) giocatore.setNomeFSCambiato(""",E8,""");"))
A9: 112712 | B9: ederson | C9: Ata | D9: =VLOOKUP(1000000+A9,'Quotazioni calciatori'!C:N,12,FALSE) -> 5792 | E9: =VLOOKUP(D9,'Leghe Fantacalcio'!B:D,3,FALSE) -> Ederson D.S. | F9: =EXACT(UPPER(B9),UPPER(E9)) -> FALSE | G9: =IF(F9,"",CONCATENATE("if (giocatore.getSquadra().equalsIgnoreCase(""",C9,""") && giocatore.getNomeFS().equalsIgnoreCase(""",B9,""")) giocatore.setNomeFSCambiato(""",E9,""");")) -> if (giocatore.getSquadra().equalsIgnoreCase("Ata") && giocatore.getNomeFS().equalsIgnoreCase("ederson")) giocatore.setNomeFSCambiato("Ederson D.S.");
A10: 35059 | B10: berardi | C10: Sas | D10: =VLOOKUP(1000000+A10,'Quotazioni calciatori'!C:N,12,FALSE) -> 531 | E10: =VLOOKUP(D10,'Leghe Fantacalcio'!B:D,3,FALSE) -> Berardi | F10: =EXACT(UPPER(B10),UPPER(E10)) -> TRUE | G10: =IF(F10,"",CONCATENATE("if (giocatore.getSquadra().equalsIgnoreCase(""",C10,""") && giocatore.getNomeFS().equalsIgnoreCase(""",B10,""")) giocatore.setNomeFSCambiato(""",E10,""");"))
A11: 95769 | B11: krstovic | C11: Ata | D11: =VLOOKUP(1000000+A11,'Quotazioni calciatori'!C:N,12,FALSE) -> 6435 | E11: =VLOOKUP(D11,'Leghe Fantacalcio'!B:D,3,FALSE) -> Krstovic | F11: =EXACT(UPPER(B11),UPPER(E11)) -> TRUE | G11: =IF(F11,"",CONCATENATE("if (giocatore.getSquadra().equalsIgnoreCase(""",C11,""") && giocatore.getNomeFS().equalsIgnoreCase(""",B11,""")) giocatore.setNomeFSCambiato(""",E11,""");"))
A12: 95108 | B12: woltemade | C12: Juv | D12: =VLOOKUP(1000000+A12,'Quotazioni calciatori'!C:N,12,FALSE) -> 6752 | E12: =VLOOKUP(D12,'Leghe Fantacalcio'!B:D,3,FALSE) -> Woltemade | F12: =EXACT(UPPER(B12),UPPER(E12)) -> TRUE | G12: =IF(F12,"",CONCATENATE("if (giocatore.getSquadra().equalsIgnoreCase(""",C12,""") && giocatore.getNomeFS().equalsIgnoreCase(""",B12,""")) giocatore.setNomeFSCambiato(""",E12,""");"))
A13: 42646 | B13: maignan | C13: Mil | D13: =VLOOKUP(1000000+A13,'Quotazioni calciatori'!C:N,12,FALSE) -> 4312 | E13: =VLOOKUP(D13,'Leghe Fantacalcio'!B:D,3,FALSE) -> Maignan | F13: =EXACT(UPPER(B13),UPPER(E13)) -> TRUE | G13: =IF(F13,"",CONCATENATE("if (giocatore.getSquadra().equalsIgnoreCase(""",C13,""") && giocatore.getNomeFS().equalsIgnoreCase(""",B13,""")) giocatore.setNomeFSCambiato(""",E13,""");"))
... A198: 67777 | B198: martinez | C198: Int | D198: =VLOOKUP(1000000+A198,'Quotazioni calciatori'!C:N,12,FALSE) -> 2764 | E198: =VLOOKUP(D198,'Leghe Fantacalcio'!B:D,3,FALSE) -> Martinez L. | F198: =EXACT(UPPER(B198),UPPER(E198)) -> FALSE | G198: =IF(F198,"",CONCATENATE("if (giocatore.getSquadra().equalsIgnoreCase(""",C198,""") && giocatore.getNomeFS().equalsIgnoreCase(""",B198,""")) giocatore.setNomeFSCambiato(""",E198,""");")) -> if (giocatore.getSquadra().equalsIgnoreCase("Int") && giocatore.getNomeFS().equalsIgnoreCase("martinez")) giocatore.setNomeFSCambiato("Martinez L.");
